[2023-09-07 18:36:07,093] * [ERROR] Internal Server Error: /1/subscribe/ C:\Users\user\PycharmProjects\D13\venv\lib\site-packages\django\utils\log.py (<class 'board.models.Category.DoesNotExist'>, DoesNotExist('Category matching query does not exist.'), <traceback object at 0x000001CE8E21CA80>)
Traceback (most recent call last):
  File "C:\Users\user\PycharmProjects\D13\venv\lib\site-packages\django\core\handlers\exception.py", line 55, in inner
    response = get_response(request)
  File "C:\Users\user\PycharmProjects\D13\venv\lib\site-packages\django\core\handlers\base.py", line 197, in _get_response
    response = wrapped_callback(request, *callback_args, **callback_kwargs)
  File "C:\Users\user\PycharmProjects\D13\venv\lib\site-packages\django\views\generic\base.py", line 104, in view
    return self.dispatch(request, *args, **kwargs)
  File "C:\Users\user\PycharmProjects\D13\venv\lib\site-packages\django\contrib\auth\mixins.py", line 73, in dispatch
    return super().dispatch(request, *args, **kwargs)
  File "C:\Users\user\PycharmProjects\D13\venv\lib\site-packages\django\views\generic\base.py", line 143, in dispatch
    return handler(request, *args, **kwargs)
  File "C:\Users\user\PycharmProjects\D13\venv\lib\site-packages\django\views\generic\base.py", line 226, in get
    context = self.get_context_data(**kwargs)
  File "C:\Users\user\PycharmProjects\D13\MMORPG\board\views.py", line 18, in get_context_data
    UsersSubscribed.objects.create(user=self.request.user, category=Category.objects.get(pk=context['pk']))
  File "C:\Users\user\PycharmProjects\D13\venv\lib\site-packages\django\db\models\manager.py", line 87, in manager_method
    return getattr(self.get_queryset(), name)(*args, **kwargs)
  File "C:\Users\user\PycharmProjects\D13\venv\lib\site-packages\django\db\models\query.py", line 637, in get
    raise self.model.DoesNotExist(
board.models.Category.DoesNotExist: Category matching query does not exist.
[2023-09-07 18:36:07,118] * [ERROR] "GET /1/subscribe/ HTTP/1.1" 500 96988 C:\Users\user\PycharmProjects\D13\venv\lib\site-packages\django\core\servers\basehttp.py None
[2023-09-08 11:49:28,242] * [ERROR] Internal Server Error: /2 C:\Users\user\PycharmProjects\D13\venv\lib\site-packages\django\utils\log.py (<class 'ValueError'>, ValueError('Cannot assign "<SimpleLazyObject: <django.contrib.auth.models.AnonymousUser object at 0x000002177A0C75E0>>": "Comment.userEditor" must be a "User" instance.'), <traceback object at 0x000002177A16EE40>)
Traceback (most recent call last):
  File "C:\Users\user\PycharmProjects\D13\venv\lib\site-packages\django\core\handlers\exception.py", line 55, in inner
    response = get_response(request)
  File "C:\Users\user\PycharmProjects\D13\venv\lib\site-packages\django\core\handlers\base.py", line 197, in _get_response
    response = wrapped_callback(request, *callback_args, **callback_kwargs)
  File "C:\Users\user\PycharmProjects\D13\venv\lib\site-packages\django\views\generic\base.py", line 104, in view
    return self.dispatch(request, *args, **kwargs)
  File "C:\Users\user\PycharmProjects\D13\venv\lib\site-packages\django\views\generic\base.py", line 143, in dispatch
    return handler(request, *args, **kwargs)
  File "C:\Users\user\PycharmProjects\D13\MMORPG\board\views.py", line 65, in post
    new_comment = Comment(commentText=request.POST.get('commentText'),
  File "C:\Users\user\PycharmProjects\D13\venv\lib\site-packages\django\db\models\base.py", line 543, in __init__
    _setattr(self, field.name, rel_obj)
  File "C:\Users\user\PycharmProjects\D13\venv\lib\site-packages\django\db\models\fields\related_descriptors.py", line 266, in __set__
    raise ValueError(
ValueError: Cannot assign "<SimpleLazyObject: <django.contrib.auth.models.AnonymousUser object at 0x000002177A0C75E0>>": "Comment.userEditor" must be a "User" instance.
[2023-09-08 11:49:28,273] * [ERROR] "POST /2 HTTP/1.1" 500 91334 C:\Users\user\PycharmProjects\D13\venv\lib\site-packages\django\core\servers\basehttp.py None
